Workbook

Sheet Presupuesto Ciete
A1: E.S. Nº: | B1: ES334500 | C1: 46148
A2: Nombre: | B2: =Cuadro!C19 -> E.S. LA SENYERA I - Nº33450
A3: Localidad: | B3: =CONCATENATE(Cuadro!I5," (",Cuadro!I6,")") -> CUART DE POBLET (VALENCIA)
A4: Trabajo encargado por: | B4: Beatriz Llueca
B7: Legalización | D7: OFERTA PRECIOS ACUERDO MARCO
A8: Item | B8: Descripción | C8: Código MOEVE | D8: Unidades | E8: Precio unidad | F8: Total
A9: 1 | B9: SERVICIO DIRECCION DE PROYECTO | C9: =IF($B9="","",VLOOKUP($B9,TARIFARIO!$C$3:$E$200,2,FALSE)) -> 165052 | D9: 40 | E9: =IF($B9="","0",VLOOKUP($B9,TARIFARIO!$C$3:$E$200,3,FALSE)) -> 40 | F9: =D9*E9 -> 1600
B10: Gestiones con ayuntamiento de Quart entre 16-12-2020 y el 06-08-2024
A11: 2 | B11: TOMA DE DATOS SIMPLE | C11: =IF($B11="","",VLOOKUP($B11,TARIFARIO!$C$3:$E$200,2,FALSE)) -> 165023 | D11: 3 | E11: =IF($B11="","0",VLOOKUP($B11,TARIFARIO!$C$3:$E$200,3,FALSE)) -> 510 | F11: =D11*E11 -> 1530
B12: 02/03/2021 Vista ES y Ayto 14/03/2022 Toma de datos edificio 30/04/2026 Visita de verificación con el técnico
A13: 3 | B13: PJT LEGA. ACTI./INST. PJT CMPT INSTALA. | C13: =IF($B13="","",VLOOKUP($B13,TARIFARIO!$C$3:$E$200,2,FALSE)) -> 181871 | D13: 1 | E13: =IF($B13="","0",VLOOKUP($B13,TARIFARIO!$C$3:$E$200,3,FALSE)) -> 2550 | F13: =D13*E13 -> 2550
B14: Proyecto legalización 08/2024
A15: 4 | B15: PROYECTO OFICIAL. MEDIO | C15: =IF($B15="","",VLOOKUP($B15,TARIFARIO!$C$3:$E$200,2,FALSE)) -> 165027 | D15: 1 | E15: =IF($B15="","0",VLOOKUP($B15,TARIFARIO!$C$3:$E$200,3,FALSE)) -> 1250 | F15: =D15*E15 -> 1250
A16: 5 | B16: INGENIERIA DE DETALLE. MEDIO | C16: =IF($B16="","",VLOOKUP($B16,TARIFARIO!$C$3:$E$200,2,FALSE)) -> 165031 | D16: 1 | E16: =IF($B16="","0",VLOOKUP($B16,TARIFARIO!$C$3:$E$200,3,FALSE)) -> 2000 | F16: =D16*E16 -> 2000
B17: Proyecto de obras de legalización
A18: 6 | B18: CFO PROYECTO COMPLEJO | C18: =IF($B18="","",VLOOKUP($B18,TARIFARIO!$C$3:$E$200,2,FALSE)) -> 181825 | D18: 1 | E18: =IF($B18="","0",VLOOKUP($B18,TARIFARIO!$C$3:$E$200,3,FALSE)) -> 790 | F18: =D18*E18 -> 790
B19: Certificado final de obras y actividad
A20: 7 | B20: OBT. AYTO DE LICENCIA PJT CMPT INSTALA. | C20: =IF($B20="","",VLOOKUP($B20,TARIFARIO!$C$3:$E$200,2,FALSE)) -> 181874 | D20: 1 | E20: =IF($B20="","0",VLOOKUP($B20,TARIFARIO!$C$3:$E$200,3,FALSE)) -> 1825 | F20: =D20*E20 -> 1825
B21: Licencia ambiental y obras
A22: 8 | B22: OBT. AYTO DE LICENCIA PJT CMPT INSTALA. | C22: =IF($B22="","",VLOOKUP($B22,TARIFARIO!$C$3:$E$200,2,FALSE)) -> 181874 | D22: 1 | E22: =IF($B22="","0",VLOOKUP($B22,TARIFARIO!$C$3:$E$200,3,FALSE)) -> 1825 | F22: =D22*E22 -> 1825
B23: Licencia de funcionamiento
A24: 9 | B24: ESTUDIO OBTENCION CERTIF. COMP URBANIST | C24: =IF($B24="","",VLOOKUP($B24,TARIFARIO!$C$3:$E$200,2,FALSE)) -> 165042 | D24: 1 | E24: =IF($B24="","0",VLOOKUP($B24,TARIFARIO!$C$3:$E$200,3,FALSE)) -> 570 | F24: =D24*E24 -> 570
B25: CCU
E29: Total: | F29: =SUM(F9:F28) -> 13940
A32: Nota: | B32: Serán de aplicación las condiciones del Contrato para Proyecto de Ingeniería entre MOEVE y Ciete.
B37: APROBADO POR:
B42: César García Villalonga

Sheet Exportar CSV Comas
A1: Producto | B1: Posición de la cesta | C1: Cantidad | D1: Fecha de entrega | E1: Mercado | F1: Características | G1: Nota interna | H1: Tipo de Multi-imputación | I1: % Cantidad, Valor de Multi-imputación | J1: Tipo de imputación | K1: Elemento de imputación | L1: Cuenta de mayor | M1: Indicador de IVA | N1: Documento presupuestario | O1: Contrato | P1: Tangible/intangible | Q1: Aprobadores | R1: Almacen | S1: Texto Proveedor | T1: CLIENTE
A2: =IF('Presupuesto Ciete'!C9="","",'Presupuesto Ciete'!C9) -> 165052 | B2: =IF('Presupuesto Ciete'!B9="","",'Presupuesto Ciete'!A9) -> 1 | C2: =IF('Presupuesto Ciete'!D9="","",'Presupuesto Ciete'!D9) -> 40 | S2: =IF('Presupuesto Ciete'!B9="","",'Presupuesto Ciete'!B9) -> SERVICIO DIRECCION DE PROYECTO | T2: =IF(A2="","",'Presupuesto Ciete'!$B$1) -> ES334500
A3: =IF('Presupuesto Ciete'!C11="","",'Presupuesto Ciete'!C11) -> 165023 | B3: =IF('Presupuesto Ciete'!B11="","",'Presupuesto Ciete'!A11) -> 2 | C3: =IF('Presupuesto Ciete'!D11="","",'Presupuesto Ciete'!D11) -> 3 | S3: =IF('Presupuesto Ciete'!B11="","",'Presupuesto Ciete'!B11) -> TOMA DE DATOS SIMPLE | T3: =IF(A3="","",'Presupuesto Ciete'!$B$1) -> ES334500
A4: =IF('Presupuesto Ciete'!C13="","",'Presupuesto Ciete'!C13) -> 181871 | B4: =IF('Presupuesto Ciete'!B13="","",'Presupuesto Ciete'!A13) -> 3 | C4: =IF('Presupuesto Ciete'!D13="","",'Presupuesto Ciete'!D13) -> 1 | S4: =IF('Presupuesto Ciete'!B13="","",'Presupuesto Ciete'!B13) -> PJT LEGA. ACTI./INST. PJT CMPT INSTALA. | T4: =IF(A4="","",'Presupuesto Ciete'!$B$1) -> ES334500
A5: =IF('Presupuesto Ciete'!C15="","",'Presupuesto Ciete'!C15) -> 165027 | B5: =IF('Presupuesto Ciete'!B15="","",'Presupuesto Ciete'!A15) -> 4 | C5: =IF('Presupuesto Ciete'!D15="","",'Presupuesto Ciete'!D15) -> 1 | S5: =IF('Presupuesto Ciete'!B15="","",'Presupuesto Ciete'!B15) -> PROYECTO OFICIAL. MEDIO | T5: =IF(A5="","",'Presupuesto Ciete'!$B$1) -> ES334500
A6: =IF('Presupuesto Ciete'!C16="","",'Presupuesto Ciete'!C16) -> 165031 | B6: =IF('Presupuesto Ciete'!B16="","",'Presupuesto Ciete'!A16) -> 5 | C6: =IF('Presupuesto Ciete'!D16="","",'Presupuesto Ciete'!D16) -> 1 | S6: =IF('Presupuesto Ciete'!B16="","",'Presupuesto Ciete'!B16) -> INGENIERIA DE DETALLE. MEDIO | T6: =IF(A6="","",'Presupuesto Ciete'!$B$1) -> ES334500
A7: =IF('Presupuesto Ciete'!C18="","",'Presupuesto Ciete'!C18) -> 181825 | B7: =IF('Presupuesto Ciete'!B18="","",'Presupuesto Ciete'!A18) -> 6 | C7: =IF('Presupuesto Ciete'!D18="","",'Presupuesto Ciete'!D18) -> 1 | S7: =IF('Presupuesto Ciete'!B18="","",'Presupuesto Ciete'!B18) -> CFO PROYECTO COMPLEJO | T7: =IF(A7="","",'Presupuesto Ciete'!$B$1) -> ES334500
A8: =IF('Presupuesto Ciete'!C20="","",'Presupuesto Ciete'!C20) -> 181874 | B8: =IF('Presupuesto Ciete'!B20="","",'Presupuesto Ciete'!A20) -> 7 | C8: =IF('Presupuesto Ciete'!D20="","",'Presupuesto Ciete'!D20) -> 1 | S8: =IF('Presupuesto Ciete'!B20="","",'Presupuesto Ciete'!B20) -> OBT. AYTO DE LICENCIA PJT CMPT INSTALA. | T8: =IF(A8="","",'Presupuesto Ciete'!$B$1) -> ES334500
A9: =IF('Presupuesto Ciete'!C22="","",'Presupuesto Ciete'!C22) -> 181874 | B9: =IF('Presupuesto Ciete'!B22="","",'Presupuesto Ciete'!A22) -> 8 | C9: =IF('Presupuesto Ciete'!D22="","",'Presupuesto Ciete'!D22) -> 1 | S9: =IF('Presupuesto Ciete'!B22="","",'Presupuesto Ciete'!B22) -> OBT. AYTO DE LICENCIA PJT CMPT INSTALA. | T9: =IF(A9="","",'Presupuesto Ciete'!$B$1) -> ES334500
A10: =IF('Presupuesto Ciete'!C24="","",'Presupuesto Ciete'!C24) -> 165042 | B10: =IF('Presupuesto Ciete'!B24="","",'Presupuesto Ciete'!A24) -> 9 | C10: =IF('Presupuesto Ciete'!D24="","",'Presupuesto Ciete'!D24) -> 1 | S10: =IF('Presupuesto Ciete'!B24="","",'Presupuesto Ciete'!B24) -> ESTUDIO OBTENCION CERTIF. COMP URBANIST | T10: =IF(A10="","",'Presupuesto Ciete'!$B$1) -> ES334500
A11: =IF('Presupuesto Ciete'!C26="","",'Presupuesto Ciete'!C26) | B11: =IF('Presupuesto Ciete'!B26="","",'Presupuesto Ciete'!A26) | C11: =IF('Presupuesto Ciete'!D26="","",'Presupuesto Ciete'!D26) | S11: =IF('Presupuesto Ciete'!B26="","",'Presupuesto Ciete'!B26) | T11: =IF(A11="","",'Presupuesto Ciete'!$B$1)
A12: =IF('Presupuesto Ciete'!C27="","",'Presupuesto Ciete'!C27) | B12: =IF('Presupuesto Ciete'!B27="","",'Presupuesto Ciete'!A27) | C12: =IF('Presupuesto Ciete'!D27="","",'Presupuesto Ciete'!D27) | S12: =IF('Presupuesto Ciete'!B27="","",'Presupuesto Ciete'!B27) | T12: =IF(A12="","",'Presupuesto Ciete'!$B$1)
A13: =IF('Presupuesto Ciete'!C28="","",'Presupuesto Ciete'!C28) | B13: =IF('Presupuesto Ciete'!B28="","",'Presupuesto Ciete'!A28) | C13: =IF('Presupuesto Ciete'!D28="","",'Presupuesto Ciete'!D28) | S13: =IF('Presupuesto Ciete'!B28="","",'Presupuesto Ciete'!B28) | T13: =IF(A13="","",'Presupuesto Ciete'!$B$1)
A14: =IF('Presupuesto Ciete'!C29="","",'Presupuesto Ciete'!C29) | B14: =IF('Presupuesto Ciete'!B29="","",'Presupuesto Ciete'!A29) | C14: =IF('Presupuesto Ciete'!D29="","",'Presupuesto Ciete'!D29) | S14: =IF('Presupuesto Ciete'!B29="","",'Presupuesto Ciete'!B29) | T14: =IF(A14="","",'Presupuesto Ciete'!$B$1)
A15: =IF('Presupuesto Ciete'!C30="","",'Presupuesto Ciete'!C30) | B15: =IF('Presupuesto Ciete'!B30="","",'Presupuesto Ciete'!A30) | C15: =IF('Presupuesto Ciete'!D30="","",'Presupuesto Ciete'!D30) | S15: =IF('Presupuesto Ciete'!B30="","",'Presupuesto Ciete'!B30) | T15: =IF(A15="","",'Presupuesto Ciete'!$B$1)
A16: =IF('Presupuesto Ciete'!C31="","",'Presupuesto Ciete'!C31) | B16: =IF('Presupuesto Ciete'!B31="","",'Presupuesto Ciete'!A31) | C16: =IF('Presupuesto Ciete'!D31="","",'Presupuesto Ciete'!D31) | S16: =IF('Presupuesto Ciete'!B31="","",'Presupuesto Ciete'!B31) | T16: =IF(A16="","",'Presupuesto Ciete'!$B$1)

Sheet Cuadro
B2: ARIBA- TRAMITACION DE PEDIDOS
B4: Propuesta de Inversión - \Opex acción gasto | H4: Dirección | I4: =VLOOKUP(I9,'Listado ES'!A:F,3,FALSE) -> A-3 PK 345
B5: Acción de gasto AC | I5: =VLOOKUP(I9,'Listado ES'!A:F,5,FALSE) -> CUART DE POBLET
B6: Sociedad | C6: 1024 | H6: Provincia | I6: =VLOOKUP(I9,'Listado ES'!A:F,6,FALSE) -> VALENCIA
B7: Cta. de Mayor
B8: ID de producto/ ID del contrato | C8: Producto | D8: Cantidad | E8: Texto Proveedor
C9: ='Exportar CSV Comas'!A2 -> 165052 | D9: ='Exportar CSV Comas'!C2 -> 40 | E9: ='Exportar CSV Comas'!S2 -> SERVICIO DIRECCION DE PROYECTO | H9: =VLOOKUP(I9,'Listado ES'!A:F,2,FALSE) -> LA SENYERA I | I9: =LEFT(RIGHT('Presupuesto Ciete'!B1,6),5)+1-1 -> 33450
C10: ='Exportar CSV Comas'!A3 -> 165023 | D10: ='Exportar CSV Comas'!C3 -> 3 | E10: ='Exportar CSV Comas'!S3 -> TOMA DE DATOS SIMPLE
C11: ='Exportar CSV Comas'!A4 -> 181871 | D11: ='Exportar CSV Comas'!C4 -> 1 | E11: ='Exportar CSV Comas'!S4 -> PJT LEGA. ACTI./INST. PJT CMPT INSTALA.
C12: ='Exportar CSV Comas'!A5 -> 165027 | D12: ='Exportar CSV Comas'!C5 -> 1 | E12: ='Exportar CSV Comas'!S5 -> PROYECTO OFICIAL. MEDIO
C13: ='Exportar CSV Comas'!A6 -> 165031 | D13: ='Exportar CSV Comas'!C6 -> 1 | E13: ='Exportar CSV Comas'!S6 -> INGENIERIA DE DETALLE. MEDIO
C14: ='Exportar CSV Comas'!A7 -> 181825 | D14: ='Exportar CSV Comas'!C7 -> 1 | E14: ='Exportar CSV Comas'!S7 -> CFO PROYECTO COMPLEJO
C15: ='Exportar CSV Comas'!A8 -> 181874 | D15: ='Exportar CSV Comas'!C8 -> 1 | E15: ='Exportar CSV Comas'!S8 -> OBT. AYTO DE LICENCIA PJT CMPT INSTALA.
C16: ='Exportar CSV Comas'!A9 -> 181874 | D16: ='Exportar CSV Comas'!C9 -> 1 | E16: ='Exportar CSV Comas'!S9 -> OBT. AYTO DE LICENCIA PJT CMPT INSTALA.
C17: ='Exportar CSV Comas'!A10 -> 165042 | D17: ='Exportar CSV Comas'!C10 -> 1 | E17: ='Exportar CSV Comas'!S10 -> ESTUDIO OBTENCION CERTIF. COMP URBANIST
B18: Descripción | C18: ='Presupuesto Ciete'!B7 -> Legalización
B19: Centro /Concesión | C19: =CONCATENATE("E.S. ",H9," - Nº",I9) -> E.S. LA SENYERA I - Nº33450
B20: Precio | C20: ='Presupuesto Ciete'!F29 -> 13940
B21: Proveedor/ Contrato | C21: 8010023472 / CIETE, S.A.
B22: Confirmar | C22: SI/NO

Sheet TARIFARIO
B2: Código | C2: Servicio | D2: Código | E2: Importe
B3: 165023 | C3: TOMA DE DATOS SIMPLE | D3: 165023 | E3: 510
B4: 181784 | C4: TOMA DE DATOS COMPLEJA | D4: 181784 | E4: 610
B5: 181785 | C5: TOMA DE DATOS C. LTO. TOPOG. PEQUEÑA | D5: 181785 | E5: 880
B6: 181786 | C6: TOMA DE DATOS C. LTO. TOPOG. MEDIANA | D6: 181786 | E6: 1400
B7: 181787 | C7: TOMA DE DATOS C. LTO. TOPOG. GRANDE | D7: 181787 | E7: 1600
B8: 165488 | C8: CREACIÓN LAYOUT GENERAL | D8: 165488 | E8: 292
B9: 165069 | C9: GESTION DE SUMINISTROS. 1 UNIDAD | D9: 165069 | E9: 200
B10: 165070 | C10: GESTION DE SUMINISTROS. 2 UNIDAD | D10: 165070 | E10: 350
B11: 165071 | C11: GESTION DE SUMINISTROS. 3 UNIDAD | D11: 165071 | E11: 400
B12: 165072 | C12: GESTION DE SUMINISTROS. 4 UNIDAD | D12: 165072 | E12: 450
B13: 181788 | C13: ESTUDIO DE VISIBILIDAD DE MONOPOSTES | D13: 181788 | E13: 920
B14: 181789 | C14: ESTI. PRE. COSTE DE EJE.(+100%,-50%) S. | D14: 181789 | E14: 300
... B173: 181900 | C173: ANALISIS DOCUMENTAL | D173: 181900 | E173: 25

Sheet Listado ES
A1: CONCESION | B1: NOMBRE | C1: DIRECCION | D1: COD. POSTAL | E1: POBLACION | F1: PROVINCIA
A2: 71 | B2: AYAMONTE | C2: MUELLE PORTUGAL, S/N | D2: 21400 | E2: AYAMONTE | F2: HUELVA
A3: 202 | B3: FRAGA | C3: N-IIA PK 437,2 | D3: 22520 | E3: FRAGA | F3: HUESCA
A4: 262 | B4: PEDRO MUÑOZ | C4: N-420 PK 313,6 | D4: 13620 | E4: PEDRO MUÑOZ | F4: CIUDAD REAL
A5: 270 | B5: TORRES MARQUEZ | C5: CM-400 PK 129 | D5: 13700 | E5: TOMELLOSO | F5: CIUDAD REAL
A6: 452 | B6: GLORIETA DEL CID | C6: GLORIETA DEL CID, S/N | D6: 41004 | E6: SEVILLA | F6: SEVILLA
A7: 464 | B7: ALCONCHEL | C7: EX-107 PK 43,5 | D7: 06131 | E7: ALCONCHEL | F7: BADAJOZ
A8: 566 | B8: PARALELO | C8: AVDA. PARALELO, 179 | D8: 08004 | E8: BARCELONA | F8: BARCELONA
A9: 632 | B9: EK22 P.P. ISLA CRISTINA | C9: PUERTO PESQUERO, MUELLE MARINA (NORTE), S/N | D9: 21410 | E9: ISLA CRISTINA | F9: HUELVA
A10: 649 | B10: UTRERA | C10: A-376 PK 40,3 | D10: 41710 | E10: UTRERA | F10: SEVILLA
A11: 655 | B11: PACIFICO | C11: AVDA. CIUDAD DE BARCELONA, 61 | D11: 28007 | E11: MADRID | F11: MADRID
A12: 661 | B12: BAÑERA | C12: A-127 PK 32,3 | D12: 50600 | E12: EJEA DE LOS CABALLEROS | F12: ZARAGOZA
A13: 708 | B13: EL ARAHAL | C13: A-92A PK 45 | D13: 41600 | E13: EL ARAHAL | F13: SEVILLA
... A1399: 33936 | B1399: PETROLARANJUEZ | C1399: A-4 PK 47,3 | D1399: 28300 | E1399: ARANJUEZ | F1399: MADRID
A1400: alda | B1400: SAN ANTONIO | C1400: A-358 PK 37,5 | D1400: 04740 | E1400: ROQUETAS DE MAR | F1400: ALMERIA
A1401: 33940 | B1401: LOS RAMOS | C1401: MU-300 PK 10,5 | D1401: 30589 | E1401: LOS RAMOS | F1401: MURCIA
A1402: 33956 | B1402: LINARES DE RIOFRIO | C1402: C-512 PK 53,4 | D1402: 37760 | E1402: LINARES DE RIOFRIO | F1402: SALAMANCA
A1403: 33962 | B1403: SALSADELLA | C1403: CV-10 PK 59,7 | D1403: 12186 | E1403: SALSADELLA | F1403: CASTELLON
A1404: 33968 | B1404: NTRA. SRA DE FÁTIMA | C1404: AVDA. NUESTRA SEÑORA DE FATIMA, 22 | D1404: 28047 | E1404: MADRID | F1404: MADRID
A1405: 33973 | B1405: A GANDARA | C1405: AVDA. DEL MAR, 96 - P.I. LA GANDARA, PARCELAS 96-97 | D1405: 15570 | E1405: NARON | F1405: LA CORUÑA
A1406: 33977 | B1406: CARO | C1406: A-92 PK 280,6 | D1406: 18181 | E1406: DARRO | F1406: GRANADA
A1407: 33979 | B1407: LA PINADA | C1407: N-234A PK 3,2 | D1407: 46500 | E1407: SAGUNTO | F1407: VALENCIA
A1408: 33988 | B1408: CAZALEGAS | C1408: N-VA PK 108,7 | D1408: 45683 | E1408: CAZALEGAS | F1408: TOLEDO
A1409: 33992 | B1409: E.S. ZALLA | C1409: EL BAULAR, 11 | D1409: 48860 | E1409: ZALLA | F1409: VIZCAYA
A1410: 33995 | B1410: LEPE CARBURANTES | C1410: N-431 PK 116,5 | D1410: 21440 | E1410: LEPE | F1410: HUELVA
A1411: 34002 | B1411: VILLARROBLEDO II | C1411: N-310A PK 131,5 | D1411: 02600 | E1411: VILLARROBLEDO | F1411: ALBACETE
A1412: 34010 | B1412: MORALEJA DE ENMEDIO | C1412: M-413 PK 3,8 | D1412: 28950 | E1412: MORALEJA DE ENMEDIO | F1412: MADRID
... A1900: 85026 | B1900: LAS MARGARITAS | C1900: DALIA ESQ. PASEO DE LAS MARGARITAS | D1900: 52006 | E1900: MELILLA | F1900: MELILLA
A1901: 85027 | B1901: PETROIL YACHT TERMINAL | C1901: WATERPORT, 1-B | E1901: GIBRALTAR | F1901: GIBRALTAR
A1902: 85028 | B1902: QUEENSWAY | C1902: QUEENSWAY, 2 | E1902: GIBRALTAR | F1902: GIBRALTAR
A1903: 85029 | B1903: ROSIA | C1903: RONDA ROSIA, 24 | E1903: GIBRALTAR | F1903: GIBRALTAR
A1904: 85031 | B1904: PETROIL SUNDIAL | C1904: AVDA. WINSTON CHURCHILL, 13 | E1904: GIBRALTAR | F1904: GIBRALTAR
A1905: 85032 | B1905: VIRGEN DEL CARMEN | C1905: ZONA DE SERVICIO DEL PUERTO DE MELILLA, S/N | D1905: 52006 | E1905: MELILLA | F1905: MELILLA
A1906: 85036 | B1906: PUERTO GIBRALTAR | C1906: MUELLE PUERTO DEPORTIVO DE GIBRALTAR | E1906: GIBRALTAR | F1906: GIBRALTAR
A1907: 85038 | B1907: CAÑONERO DATO | C1907: AVENIDA CAÑORERO DATO, 101 | D1907: 51001 | E1907: CEUTA | F1907: CEUTA
A1908: 86001 | B1908: SANT JULIA I | C1908: CG-1 PK 6 | E1908: SANT JULIA DE LORIA | F1908: SANT JULIA DE LORIA
A1909: 86003 | B1909: ENCAMP | C1909: CG-2 PK 5,5 | E1909: ENCAMP | F1909: ENCAMP
A1910: 86007 | B1910: SANTA COLOMA | C1910: CG-1 PK 1 | E1910: ANDORRA LA VELLA | F1910: ANDORRA LA VELLA
A1911: 86008 | B1911: L'OBAC | C1911: AVDA. SALOU, 68 | E1911: ANDORRA LA VELLA | F1911: ANDORRA LA VELLA
A1912: 86009 | B1912: ENCAMP CENTRE | C1912: CG-2 PK 6 | E1912: ENCAMP | F1912: ENCAMP
...
